[2024-11-20T23:51:28.388+0000] {local_task_job_runner.py:123} INFO - ::group::Pre task execution logs
[2024-11-20T23:51:28.408+0000] {taskinstance.py:2613} INFO - Dependencies all met for dep_context=non-requeueable deps ti=<TaskInstance: process_heart_disease_data.upload_to_google_sheets manual__2024-11-20T23:20:19.171028+00:00 [queued]>
[2024-11-20T23:51:28.416+0000] {taskinstance.py:2613} INFO - Dependencies all met for dep_context=requeueable deps ti=<TaskInstance: process_heart_disease_data.upload_to_google_sheets manual__2024-11-20T23:20:19.171028+00:00 [queued]>
[2024-11-20T23:51:28.417+0000] {taskinstance.py:2866} INFO - Starting attempt 2 of 2
[2024-11-20T23:51:28.431+0000] {taskinstance.py:2889} INFO - Executing <Task(PythonOperator): upload_to_google_sheets> on 2024-11-20 23:20:19.171028+00:00
[2024-11-20T23:51:28.450+0000] {logging_mixin.py:190} WARNING - /home/***/.local/lib/python3.12/site-packages/***/task/task_runner/standard_task_runner.py:70 DeprecationWarning: This process (pid=873) is multi-threaded, use of fork() may lead to deadlocks in the child.
[2024-11-20T23:51:28.446+0000] {standard_task_runner.py:104} INFO - Running: ['***', 'tasks', 'run', 'process_heart_disease_data', 'upload_to_google_sheets', 'manual__2024-11-20T23:20:19.171028+00:00', '--job-id', '56', '--raw', '--subdir', 'DAGS_FOLDER/dag1.py', '--cfg-path', '/tmp/tmp4fwno46j']
[2024-11-20T23:51:28.454+0000] {standard_task_runner.py:72} INFO - Started process 890 to run task
[2024-11-20T23:51:28.454+0000] {standard_task_runner.py:105} INFO - Job 56: Subtask upload_to_google_sheets
[2024-11-20T23:51:28.550+0000] {task_command.py:467} INFO - Running <TaskInstance: process_heart_disease_data.upload_to_google_sheets manual__2024-11-20T23:20:19.171028+00:00 [running]> on host 2276f79c0942
[2024-11-20T23:51:28.684+0000] {taskinstance.py:3132} INFO - Exporting env vars: AIRFLOW_CTX_DAG_OWNER='***' AIRFLOW_CTX_DAG_ID='process_heart_disease_data' AIRFLOW_CTX_TASK_ID='upload_to_google_sheets' AIRFLOW_CTX_EXECUTION_DATE='2024-11-20T23:20:19.171028+00:00' AIRFLOW_CTX_TRY_NUMBER='2' AIRFLOW_CTX_DAG_RUN_ID='manual__2024-11-20T23:20:19.171028+00:00'
[2024-11-20T23:51:28.685+0000] {taskinstance.py:731} INFO - ::endgroup::
[2024-11-20T23:51:32.320+0000] {taskinstance.py:3311} ERROR - Task failed with exception
Traceback (most recent call last):
  File "/home/airflow/.local/lib/python3.12/site-packages/gspread/client.py", line 155, in open_by_key
    spreadsheet = Spreadsheet(self.http_client, {"id": key})
                  ^^^^^^^^^^^^^^^^^^^^^^^^^^^^^^^^^^^^^^^^^^
  File "/home/airflow/.local/lib/python3.12/site-packages/gspread/spreadsheet.py", line 29, in __init__
    metadata = self.fetch_sheet_metadata()
               ^^^^^^^^^^^^^^^^^^^^^^^^^^^
  File "/home/airflow/.local/lib/python3.12/site-packages/gspread/spreadsheet.py", line 230, in fetch_sheet_metadata
    return self.client.fetch_sheet_metadata(self.id, params=params)
           ^^^^^^^^^^^^^^^^^^^^^^^^^^^^^^^^^^^^^^^^^^^^^^^^^^^^^^^^
  File "/home/airflow/.local/lib/python3.12/site-packages/gspread/http_client.py", line 305, in fetch_sheet_metadata
    r = self.request("get", url, params=params)
        ^^^^^^^^^^^^^^^^^^^^^^^^^^^^^^^^^^^^^^^
  File "/home/airflow/.local/lib/python3.12/site-packages/gspread/http_client.py", line 128, in request
    raise APIError(response)
gspread.exceptions.APIError: APIError: [403]: Google Sheets API has not been used in project 264330644967 before or it is disabled. Enable it by visiting https://console.developers.google.com/apis/api/sheets.googleapis.com/overview?project=264330644967 then retry. If you enabled this API recently, wait a few minutes for the action to propagate to our systems and retry.

The above exception was the direct cause of the following exception:

Traceback (most recent call last):
  File "/opt/airflow/dags/dag1.py", line 114, in upload_to_google_sheets
    sheet = client.create("Dane podzielone")
            ^^^^^^^^^^^^^^^^^^^^^^^^^^^^^^^^
  File "/home/airflow/.local/lib/python3.12/site-packages/gspread/client.py", line 225, in create
    return self.open_by_key(spreadsheet_id)
           ^^^^^^^^^^^^^^^^^^^^^^^^^^^^^^^^
  File "/home/airflow/.local/lib/python3.12/site-packages/gspread/client.py", line 160, in open_by_key
    raise PermissionError from ex
PermissionError

During handling of the above exception, another exception occurred:

Traceback (most recent call last):
  File "/home/airflow/.local/lib/python3.12/site-packages/airflow/models/taskinstance.py", line 767, in _execute_task
    result = _execute_callable(context=context, **execute_callable_kwargs)
             ^^^^^^^^^^^^^^^^^^^^^^^^^^^^^^^^^^^^^^^^^^^^^^^^^^^^^^^^^^^^^
  File "/home/airflow/.local/lib/python3.12/site-packages/airflow/models/taskinstance.py", line 733, in _execute_callable
    return ExecutionCallableRunner(
           ^^^^^^^^^^^^^^^^^^^^^^^^
  File "/home/airflow/.local/lib/python3.12/site-packages/airflow/utils/operator_helpers.py", line 252, in run
    return self.func(*args, **kwargs)
           ^^^^^^^^^^^^^^^^^^^^^^^^^^
  File "/home/airflow/.local/lib/python3.12/site-packages/airflow/models/baseoperator.py", line 417, in wrapper
    return func(self, *args, **kwargs)
           ^^^^^^^^^^^^^^^^^^^^^^^^^^^
  File "/home/airflow/.local/lib/python3.12/site-packages/airflow/operators/python.py", line 238, in execute
    return_value = self.execute_callable()
                   ^^^^^^^^^^^^^^^^^^^^^^^
  File "/home/airflow/.local/lib/python3.12/site-packages/airflow/operators/python.py", line 256, in execute_callable
    return runner.run(*self.op_args, **self.op_kwargs)
           ^^^^^^^^^^^^^^^^^^^^^^^^^^^^^^^^^^^^^^^^^^^
  File "/home/airflow/.local/lib/python3.12/site-packages/airflow/utils/operator_helpers.py", line 252, in run
    return self.func(*args, **kwargs)
           ^^^^^^^^^^^^^^^^^^^^^^^^^^
  File "/opt/airflow/dags/dag1.py", line 128, in upload_to_google_sheets
    raise Exception(f"Błąd podczas zapisywania danych w Google Sheets: {e}")
Exception: Błąd podczas zapisywania danych w Google Sheets: 
[2024-11-20T23:51:32.330+0000] {taskinstance.py:1225} INFO - Marking task as FAILED. dag_id=process_heart_disease_data, task_id=upload_to_google_sheets, run_id=manual__2024-11-20T23:20:19.171028+00:00, execution_date=20241120T232019, start_date=20241120T235128, end_date=20241120T235132
[2024-11-20T23:51:32.340+0000] {taskinstance.py:340} INFO - ::group::Post task execution logs
[2024-11-20T23:51:32.341+0000] {standard_task_runner.py:124} ERROR - Failed to execute job 56 for task upload_to_google_sheets (Błąd podczas zapisywania danych w Google Sheets: ; 890)
Traceback (most recent call last):
  File "/home/airflow/.local/lib/python3.12/site-packages/gspread/client.py", line 155, in open_by_key
    spreadsheet = Spreadsheet(self.http_client, {"id": key})
                  ^^^^^^^^^^^^^^^^^^^^^^^^^^^^^^^^^^^^^^^^^^
  File "/home/airflow/.local/lib/python3.12/site-packages/gspread/spreadsheet.py", line 29, in __init__
    metadata = self.fetch_sheet_metadata()
               ^^^^^^^^^^^^^^^^^^^^^^^^^^^
  File "/home/airflow/.local/lib/python3.12/site-packages/gspread/spreadsheet.py", line 230, in fetch_sheet_metadata
    return self.client.fetch_sheet_metadata(self.id, params=params)
           ^^^^^^^^^^^^^^^^^^^^^^^^^^^^^^^^^^^^^^^^^^^^^^^^^^^^^^^^
  File "/home/airflow/.local/lib/python3.12/site-packages/gspread/http_client.py", line 305, in fetch_sheet_metadata
    r = self.request("get", url, params=params)
        ^^^^^^^^^^^^^^^^^^^^^^^^^^^^^^^^^^^^^^^
  File "/home/airflow/.local/lib/python3.12/site-packages/gspread/http_client.py", line 128, in request
    raise APIError(response)
gspread.exceptions.APIError: APIError: [403]: Google Sheets API has not been used in project 264330644967 before or it is disabled. Enable it by visiting https://console.developers.google.com/apis/api/sheets.googleapis.com/overview?project=264330644967 then retry. If you enabled this API recently, wait a few minutes for the action to propagate to our systems and retry.

The above exception was the direct cause of the following exception:

Traceback (most recent call last):
  File "/opt/airflow/dags/dag1.py", line 114, in upload_to_google_sheets
    sheet = client.create("Dane podzielone")
            ^^^^^^^^^^^^^^^^^^^^^^^^^^^^^^^^
  File "/home/airflow/.local/lib/python3.12/site-packages/gspread/client.py", line 225, in create
    return self.open_by_key(spreadsheet_id)
           ^^^^^^^^^^^^^^^^^^^^^^^^^^^^^^^^
  File "/home/airflow/.local/lib/python3.12/site-packages/gspread/client.py", line 160, in open_by_key
    raise PermissionError from ex
PermissionError

During handling of the above exception, another exception occurred:

Traceback (most recent call last):
  File "/home/airflow/.local/lib/python3.12/site-packages/airflow/task/task_runner/standard_task_runner.py", line 117, in _start_by_fork
    ret = args.func(args, dag=self.dag)
          ^^^^^^^^^^^^^^^^^^^^^^^^^^^^^
  File "/home/airflow/.local/lib/python3.12/site-packages/airflow/cli/cli_config.py", line 49, in command
    return func(*args, **kwargs)
           ^^^^^^^^^^^^^^^^^^^^^
  File "/home/airflow/.local/lib/python3.12/site-packages/airflow/utils/cli.py", line 116, in wrapper
    return f(*args, **kwargs)
           ^^^^^^^^^^^^^^^^^^
  File "/home/airflow/.local/lib/python3.12/site-packages/airflow/cli/commands/task_command.py", line 483, in task_run
    task_return_code = _run_task_by_selected_method(args, _dag, ti)
                       ^^^^^^^^^^^^^^^^^^^^^^^^^^^^^^^^^^^^^^^^^^^^
  File "/home/airflow/.local/lib/python3.12/site-packages/airflow/cli/commands/task_command.py", line 256, in _run_task_by_selected_method
    return _run_raw_task(args, ti)
           ^^^^^^^^^^^^^^^^^^^^^^^
  File "/home/airflow/.local/lib/python3.12/site-packages/airflow/cli/commands/task_command.py", line 341, in _run_raw_task
    return ti._run_raw_task(
           ^^^^^^^^^^^^^^^^^
  File "/home/airflow/.local/lib/python3.12/site-packages/airflow/utils/session.py", line 97, in wrapper
    return func(*args, session=session, **kwargs)
           ^^^^^^^^^^^^^^^^^^^^^^^^^^^^^^^^^^^^^^
  File "/home/airflow/.local/lib/python3.12/site-packages/airflow/models/taskinstance.py", line 3005, in _run_raw_task
    return _run_raw_task(
           ^^^^^^^^^^^^^^
  File "/home/airflow/.local/lib/python3.12/site-packages/airflow/models/taskinstance.py", line 273, in _run_raw_task
    TaskInstance._execute_task_with_callbacks(
  File "/home/airflow/.local/lib/python3.12/site-packages/airflow/models/taskinstance.py", line 3159, in _execute_task_with_callbacks
    result = self._execute_task(context, task_orig)
             ^^^^^^^^^^^^^^^^^^^^^^^^^^^^^^^^^^^^^^
  File "/home/airflow/.local/lib/python3.12/site-packages/airflow/models/taskinstance.py", line 3183, in _execute_task
    return _execute_task(self, context, task_orig)
           ^^^^^^^^^^^^^^^^^^^^^^^^^^^^^^^^^^^^^^^
  File "/home/airflow/.local/lib/python3.12/site-packages/airflow/models/taskinstance.py", line 767, in _execute_task
    result = _execute_callable(context=context, **execute_callable_kwargs)
             ^^^^^^^^^^^^^^^^^^^^^^^^^^^^^^^^^^^^^^^^^^^^^^^^^^^^^^^^^^^^^
  File "/home/airflow/.local/lib/python3.12/site-packages/airflow/models/taskinstance.py", line 733, in _execute_callable
    return ExecutionCallableRunner(
           ^^^^^^^^^^^^^^^^^^^^^^^^
  File "/home/airflow/.local/lib/python3.12/site-packages/airflow/utils/operator_helpers.py", line 252, in run
    return self.func(*args, **kwargs)
           ^^^^^^^^^^^^^^^^^^^^^^^^^^
  File "/home/airflow/.local/lib/python3.12/site-packages/airflow/models/baseoperator.py", line 417, in wrapper
    return func(self, *args, **kwargs)
           ^^^^^^^^^^^^^^^^^^^^^^^^^^^
  File "/home/airflow/.local/lib/python3.12/site-packages/airflow/operators/python.py", line 238, in execute
    return_value = self.execute_callable()
                   ^^^^^^^^^^^^^^^^^^^^^^^
  File "/home/airflow/.local/lib/python3.12/site-packages/airflow/operators/python.py", line 256, in execute_callable
    return runner.run(*self.op_args, **self.op_kwargs)
           ^^^^^^^^^^^^^^^^^^^^^^^^^^^^^^^^^^^^^^^^^^^
  File "/home/airflow/.local/lib/python3.12/site-packages/airflow/utils/operator_helpers.py", line 252, in run
    return self.func(*args, **kwargs)
           ^^^^^^^^^^^^^^^^^^^^^^^^^^
  File "/opt/airflow/dags/dag1.py", line 128, in upload_to_google_sheets
    raise Exception(f"Błąd podczas zapisywania danych w Google Sheets: {e}")
Exception: Błąd podczas zapisywania danych w Google Sheets: 
[2024-11-20T23:51:32.360+0000] {local_task_job_runner.py:266} INFO - Task exited with return code 1
[2024-11-20T23:51:32.373+0000] {taskinstance.py:3895} INFO - 0 downstream tasks scheduled from follow-on schedule check
[2024-11-20T23:51:32.375+0000] {local_task_job_runner.py:245} INFO - ::endgroup::
